[2024-11-04T04:52:53.156+0000] {local_task_job_runner.py:123} INFO - ::group::Pre task execution logs
[2024-11-04T04:52:53.172+0000] {taskinstance.py:2612} INFO - Dependencies all met for dep_context=non-requeueable deps ti=<TaskInstance: stock-market-summary.hankyoung_news manual__2024-11-04T04:52:42.192827+00:00 [queued]>
[2024-11-04T04:52:53.181+0000] {taskinstance.py:2612} INFO - Dependencies all met for dep_context=requeueable deps ti=<TaskInstance: stock-market-summary.hankyoung_news manual__2024-11-04T04:52:42.192827+00:00 [queued]>
[2024-11-04T04:52:53.181+0000] {taskinstance.py:2865} INFO - Starting attempt 1 of 1
[2024-11-04T04:52:53.194+0000] {taskinstance.py:2888} INFO - Executing <Task(PythonOperator): hankyoung_news> on 2024-11-04 04:52:42.192827+00:00
[2024-11-04T04:52:53.203+0000] {warnings.py:112} WARNING - /home/***/.local/lib/python3.12/site-packages/***/task/task_runner/standard_task_runner.py:70: DeprecationWarning: This process (pid=3051) is multi-threaded, use of fork() may lead to deadlocks in the child.
  pid = os.fork()

[2024-11-04T04:52:53.204+0000] {standard_task_runner.py:72} INFO - Started process 3053 to run task
[2024-11-04T04:52:53.206+0000] {standard_task_runner.py:104} INFO - Running: ['***', 'tasks', 'run', 'stock-market-summary', 'hankyoung_news', 'manual__2024-11-04T04:52:42.192827+00:00', '--job-id', '220', '--raw', '--subdir', 'DAGS_FOLDER/stock_market_summary.py', '--cfg-path', '/tmp/tmp0a9d37ow']
[2024-11-04T04:52:53.208+0000] {standard_task_runner.py:105} INFO - Job 220: Subtask hankyoung_news
[2024-11-04T04:52:53.253+0000] {task_command.py:467} INFO - Running <TaskInstance: stock-market-summary.hankyoung_news manual__2024-11-04T04:52:42.192827+00:00 [running]> on host 5a41fc77ef88
[2024-11-04T04:52:53.333+0000] {taskinstance.py:3131} INFO - Exporting env vars: AIRFLOW_CTX_DAG_OWNER='***' AIRFLOW_CTX_DAG_ID='stock-market-summary' AIRFLOW_CTX_TASK_ID='hankyoung_news' AIRFLOW_CTX_EXECUTION_DATE='2024-11-04T04:52:42.192827+00:00' AIRFLOW_CTX_TRY_NUMBER='1' AIRFLOW_CTX_DAG_RUN_ID='manual__2024-11-04T04:52:42.192827+00:00'
[2024-11-04T04:52:53.335+0000] {taskinstance.py:731} INFO - ::endgroup::
[2024-11-04T04:53:07.944+0000] {taskinstance.py:3310} ERROR - Task failed with exception
Traceback (most recent call last):
  File "/home/airflow/.local/lib/python3.12/site-packages/urllib3/response.py", line 748, in _error_catcher
    yield
  File "/home/airflow/.local/lib/python3.12/site-packages/urllib3/response.py", line 1209, in read_chunked
    chunk = self._handle_chunk(amt)
            ^^^^^^^^^^^^^^^^^^^^^^^
  File "/home/airflow/.local/lib/python3.12/site-packages/urllib3/response.py", line 1146, in _handle_chunk
    value = self._fp._safe_read(amt)  # type: ignore[union-attr]
            ^^^^^^^^^^^^^^^^^^^^^^^^
  File "/usr/local/lib/python3.12/http/client.py", line 642, in _safe_read
    raise IncompleteRead(data, amt-len(data))
http.client.IncompleteRead: IncompleteRead(8185 bytes read, 2055 more expected)

The above exception was the direct cause of the following exception:

Traceback (most recent call last):
  File "/home/airflow/.local/lib/python3.12/site-packages/requests/models.py", line 820, in generate
    yield from self.raw.stream(chunk_size, decode_content=True)
  File "/home/airflow/.local/lib/python3.12/site-packages/urllib3/response.py", line 1057, in stream
    yield from self.read_chunked(amt, decode_content=decode_content)
  File "/home/airflow/.local/lib/python3.12/site-packages/urllib3/response.py", line 1189, in read_chunked
    with self._error_catcher():
         ^^^^^^^^^^^^^^^^^^^^^
  File "/usr/local/lib/python3.12/contextlib.py", line 158, in __exit__
    self.gen.throw(value)
  File "/home/airflow/.local/lib/python3.12/site-packages/urllib3/response.py", line 775, in _error_catcher
    raise ProtocolError(f"Connection broken: {e!r}", e) from e
urllib3.exceptions.ProtocolError: ('Connection broken: IncompleteRead(8185 bytes read, 2055 more expected)', IncompleteRead(8185 bytes read, 2055 more expected))

During handling of the above exception, another exception occurred:

Traceback (most recent call last):
  File "/home/airflow/.local/lib/python3.12/site-packages/airflow/models/taskinstance.py", line 767, in _execute_task
    result = _execute_callable(context=context, **execute_callable_kwargs)
             ^^^^^^^^^^^^^^^^^^^^^^^^^^^^^^^^^^^^^^^^^^^^^^^^^^^^^^^^^^^^^
  File "/home/airflow/.local/lib/python3.12/site-packages/airflow/models/taskinstance.py", line 733, in _execute_callable
    return ExecutionCallableRunner(
           ^^^^^^^^^^^^^^^^^^^^^^^^
  File "/home/airflow/.local/lib/python3.12/site-packages/airflow/utils/operator_helpers.py", line 252, in run
    return self.func(*args, **kwargs)
           ^^^^^^^^^^^^^^^^^^^^^^^^^^
  File "/home/airflow/.local/lib/python3.12/site-packages/airflow/models/baseoperator.py", line 406, in wrapper
    return func(self, *args, **kwargs)
           ^^^^^^^^^^^^^^^^^^^^^^^^^^^
  File "/home/airflow/.local/lib/python3.12/site-packages/airflow/operators/python.py", line 238, in execute
    return_value = self.execute_callable()
                   ^^^^^^^^^^^^^^^^^^^^^^^
  File "/home/airflow/.local/lib/python3.12/site-packages/airflow/operators/python.py", line 256, in execute_callable
    return runner.run(*self.op_args, **self.op_kwargs)
           ^^^^^^^^^^^^^^^^^^^^^^^^^^^^^^^^^^^^^^^^^^^
  File "/home/airflow/.local/lib/python3.12/site-packages/airflow/utils/operator_helpers.py", line 252, in run
    return self.func(*args, **kwargs)
           ^^^^^^^^^^^^^^^^^^^^^^^^^^
  File "/opt/airflow/dags/stock_market_summary.py", line 257, in all_hankyoung_news
    hankyoung_articles = [get_kor_economy_news(stock["name_kr"], include_content=True)
                          ^^^^^^^^^^^^^^^^^^^^^^^^^^^^^^^^^^^^^^^^^^^^^^^^^^^^^^^^^^^^
  File "/opt/airflow/dags/stock_market_summary.py", line 99, in get_kor_economy_news
    news_response = requests.get(news_url, headers={'User-Agent': chrom_ua})
                    ^^^^^^^^^^^^^^^^^^^^^^^^^^^^^^^^^^^^^^^^^^^^^^^^^^^^^^^^
  File "/home/airflow/.local/lib/python3.12/site-packages/requests/api.py", line 73, in get
    return request("get", url, params=params, **kwargs)
           ^^^^^^^^^^^^^^^^^^^^^^^^^^^^^^^^^^^^^^^^^^^^
  File "/home/airflow/.local/lib/python3.12/site-packages/requests/api.py", line 59, in request
    return session.request(method=method, url=url, **kwargs)
           ^^^^^^^^^^^^^^^^^^^^^^^^^^^^^^^^^^^^^^^^^^^^^^^^^
  File "/home/airflow/.local/lib/python3.12/site-packages/requests/sessions.py", line 589, in request
    resp = self.send(prep, **send_kwargs)
           ^^^^^^^^^^^^^^^^^^^^^^^^^^^^^^
  File "/home/airflow/.local/lib/python3.12/site-packages/requests/sessions.py", line 746, in send
    r.content
  File "/home/airflow/.local/lib/python3.12/site-packages/requests/models.py", line 902, in content
    self._content = b"".join(self.iter_content(CONTENT_CHUNK_SIZE)) or b""
                    ^^^^^^^^^^^^^^^^^^^^^^^^^^^^^^^^^^^^^^^^^^^^^^^
  File "/home/airflow/.local/lib/python3.12/site-packages/requests/models.py", line 822, in generate
    raise ChunkedEncodingError(e)
requests.exceptions.ChunkedEncodingError: ('Connection broken: IncompleteRead(8185 bytes read, 2055 more expected)', IncompleteRead(8185 bytes read, 2055 more expected))
[2024-11-04T04:53:07.965+0000] {taskinstance.py:1225} INFO - Marking task as FAILED. dag_id=stock-market-summary, task_id=hankyoung_news, run_id=manual__2024-11-04T04:52:42.192827+00:00, execution_date=20241104T045242, start_date=20241104T045253, end_date=20241104T045307
[2024-11-04T04:53:07.980+0000] {taskinstance.py:340} INFO - ::group::Post task execution logs
[2024-11-04T04:53:07.981+0000] {standard_task_runner.py:124} ERROR - Failed to execute job 220 for task hankyoung_news (('Connection broken: IncompleteRead(8185 bytes read, 2055 more expected)', IncompleteRead(8185 bytes read, 2055 more expected)); 3053)
Traceback (most recent call last):
  File "/home/airflow/.local/lib/python3.12/site-packages/urllib3/response.py", line 748, in _error_catcher
    yield
  File "/home/airflow/.local/lib/python3.12/site-packages/urllib3/response.py", line 1209, in read_chunked
    chunk = self._handle_chunk(amt)
            ^^^^^^^^^^^^^^^^^^^^^^^
  File "/home/airflow/.local/lib/python3.12/site-packages/urllib3/response.py", line 1146, in _handle_chunk
    value = self._fp._safe_read(amt)  # type: ignore[union-attr]
            ^^^^^^^^^^^^^^^^^^^^^^^^
  File "/usr/local/lib/python3.12/http/client.py", line 642, in _safe_read
    raise IncompleteRead(data, amt-len(data))
http.client.IncompleteRead: IncompleteRead(8185 bytes read, 2055 more expected)

The above exception was the direct cause of the following exception:

Traceback (most recent call last):
  File "/home/airflow/.local/lib/python3.12/site-packages/requests/models.py", line 820, in generate
    yield from self.raw.stream(chunk_size, decode_content=True)
  File "/home/airflow/.local/lib/python3.12/site-packages/urllib3/response.py", line 1057, in stream
    yield from self.read_chunked(amt, decode_content=decode_content)
  File "/home/airflow/.local/lib/python3.12/site-packages/urllib3/response.py", line 1189, in read_chunked
    with self._error_catcher():
         ^^^^^^^^^^^^^^^^^^^^^
  File "/usr/local/lib/python3.12/contextlib.py", line 158, in __exit__
    self.gen.throw(value)
  File "/home/airflow/.local/lib/python3.12/site-packages/urllib3/response.py", line 775, in _error_catcher
    raise ProtocolError(f"Connection broken: {e!r}", e) from e
urllib3.exceptions.ProtocolError: ('Connection broken: IncompleteRead(8185 bytes read, 2055 more expected)', IncompleteRead(8185 bytes read, 2055 more expected))

During handling of the above exception, another exception occurred:

Traceback (most recent call last):
  File "/home/airflow/.local/lib/python3.12/site-packages/airflow/task/task_runner/standard_task_runner.py", line 117, in _start_by_fork
    ret = args.func(args, dag=self.dag)
          ^^^^^^^^^^^^^^^^^^^^^^^^^^^^^
  File "/home/airflow/.local/lib/python3.12/site-packages/airflow/cli/cli_config.py", line 49, in command
    return func(*args, **kwargs)
           ^^^^^^^^^^^^^^^^^^^^^
  File "/home/airflow/.local/lib/python3.12/site-packages/airflow/utils/cli.py", line 115, in wrapper
    return f(*args, **kwargs)
           ^^^^^^^^^^^^^^^^^^
  File "/home/airflow/.local/lib/python3.12/site-packages/airflow/cli/commands/task_command.py", line 483, in task_run
    task_return_code = _run_task_by_selected_method(args, _dag, ti)
                       ^^^^^^^^^^^^^^^^^^^^^^^^^^^^^^^^^^^^^^^^^^^^
  File "/home/airflow/.local/lib/python3.12/site-packages/airflow/cli/commands/task_command.py", line 256, in _run_task_by_selected_method
    return _run_raw_task(args, ti)
           ^^^^^^^^^^^^^^^^^^^^^^^
  File "/home/airflow/.local/lib/python3.12/site-packages/airflow/cli/commands/task_command.py", line 341, in _run_raw_task
    return ti._run_raw_task(
           ^^^^^^^^^^^^^^^^^
  File "/home/airflow/.local/lib/python3.12/site-packages/airflow/utils/session.py", line 97, in wrapper
    return func(*args, session=session, **kwargs)
           ^^^^^^^^^^^^^^^^^^^^^^^^^^^^^^^^^^^^^^
  File "/home/airflow/.local/lib/python3.12/site-packages/airflow/models/taskinstance.py", line 3004, in _run_raw_task
    return _run_raw_task(
           ^^^^^^^^^^^^^^
  File "/home/airflow/.local/lib/python3.12/site-packages/airflow/models/taskinstance.py", line 273, in _run_raw_task
    TaskInstance._execute_task_with_callbacks(
  File "/home/airflow/.local/lib/python3.12/site-packages/airflow/models/taskinstance.py", line 3158, in _execute_task_with_callbacks
    result = self._execute_task(context, task_orig)
             ^^^^^^^^^^^^^^^^^^^^^^^^^^^^^^^^^^^^^^
  File "/home/airflow/.local/lib/python3.12/site-packages/airflow/models/taskinstance.py", line 3182, in _execute_task
    return _execute_task(self, context, task_orig)
           ^^^^^^^^^^^^^^^^^^^^^^^^^^^^^^^^^^^^^^^
  File "/home/airflow/.local/lib/python3.12/site-packages/airflow/models/taskinstance.py", line 767, in _execute_task
    result = _execute_callable(context=context, **execute_callable_kwargs)
             ^^^^^^^^^^^^^^^^^^^^^^^^^^^^^^^^^^^^^^^^^^^^^^^^^^^^^^^^^^^^^
  File "/home/airflow/.local/lib/python3.12/site-packages/airflow/models/taskinstance.py", line 733, in _execute_callable
    return ExecutionCallableRunner(
           ^^^^^^^^^^^^^^^^^^^^^^^^
  File "/home/airflow/.local/lib/python3.12/site-packages/airflow/utils/operator_helpers.py", line 252, in run
    return self.func(*args, **kwargs)
           ^^^^^^^^^^^^^^^^^^^^^^^^^^
  File "/home/airflow/.local/lib/python3.12/site-packages/airflow/models/baseoperator.py", line 406, in wrapper
    return func(self, *args, **kwargs)
           ^^^^^^^^^^^^^^^^^^^^^^^^^^^
  File "/home/airflow/.local/lib/python3.12/site-packages/airflow/operators/python.py", line 238, in execute
    return_value = self.execute_callable()
                   ^^^^^^^^^^^^^^^^^^^^^^^
  File "/home/airflow/.local/lib/python3.12/site-packages/airflow/operators/python.py", line 256, in execute_callable
    return runner.run(*self.op_args, **self.op_kwargs)
           ^^^^^^^^^^^^^^^^^^^^^^^^^^^^^^^^^^^^^^^^^^^
  File "/home/airflow/.local/lib/python3.12/site-packages/airflow/utils/operator_helpers.py", line 252, in run
    return self.func(*args, **kwargs)
           ^^^^^^^^^^^^^^^^^^^^^^^^^^
  File "/opt/airflow/dags/stock_market_summary.py", line 257, in all_hankyoung_news
    hankyoung_articles = [get_kor_economy_news(stock["name_kr"], include_content=True)
                          ^^^^^^^^^^^^^^^^^^^^^^^^^^^^^^^^^^^^^^^^^^^^^^^^^^^^^^^^^^^^
  File "/opt/airflow/dags/stock_market_summary.py", line 99, in get_kor_economy_news
    news_response = requests.get(news_url, headers={'User-Agent': chrom_ua})
                    ^^^^^^^^^^^^^^^^^^^^^^^^^^^^^^^^^^^^^^^^^^^^^^^^^^^^^^^^
  File "/home/airflow/.local/lib/python3.12/site-packages/requests/api.py", line 73, in get
    return request("get", url, params=params, **kwargs)
           ^^^^^^^^^^^^^^^^^^^^^^^^^^^^^^^^^^^^^^^^^^^^
  File "/home/airflow/.local/lib/python3.12/site-packages/requests/api.py", line 59, in request
    return session.request(method=method, url=url, **kwargs)
           ^^^^^^^^^^^^^^^^^^^^^^^^^^^^^^^^^^^^^^^^^^^^^^^^^
  File "/home/airflow/.local/lib/python3.12/site-packages/requests/sessions.py", line 589, in request
    resp = self.send(prep, **send_kwargs)
           ^^^^^^^^^^^^^^^^^^^^^^^^^^^^^^
  File "/home/airflow/.local/lib/python3.12/site-packages/requests/sessions.py", line 746, in send
    r.content
  File "/home/airflow/.local/lib/python3.12/site-packages/requests/models.py", line 902, in content
    self._content = b"".join(self.iter_content(CONTENT_CHUNK_SIZE)) or b""
                    ^^^^^^^^^^^^^^^^^^^^^^^^^^^^^^^^^^^^^^^^^^^^^^^
  File "/home/airflow/.local/lib/python3.12/site-packages/requests/models.py", line 822, in generate
    raise ChunkedEncodingError(e)
requests.exceptions.ChunkedEncodingError: ('Connection broken: IncompleteRead(8185 bytes read, 2055 more expected)', IncompleteRead(8185 bytes read, 2055 more expected))
[2024-11-04T04:53:07.996+0000] {local_task_job_runner.py:266} INFO - Task exited with return code 1
[2024-11-04T04:53:08.017+0000] {taskinstance.py:3900} INFO - 0 downstream tasks scheduled from follow-on schedule check
[2024-11-04T04:53:08.021+0000] {local_task_job_runner.py:245} INFO - ::endgroup::
