[2024-11-04T05:20:13.916+0000] {local_task_job_runner.py:123} INFO - ::group::Pre task execution logs
[2024-11-04T05:20:13.934+0000] {taskinstance.py:2612} INFO - Dependencies all met for dep_context=non-requeueable deps ti=<TaskInstance: stock-market-summary.send_slack_message manual__2024-11-04T05:19:40.405305+00:00 [queued]>
[2024-11-04T05:20:13.944+0000] {taskinstance.py:2612} INFO - Dependencies all met for dep_context=requeueable deps ti=<TaskInstance: stock-market-summary.send_slack_message manual__2024-11-04T05:19:40.405305+00:00 [queued]>
[2024-11-04T05:20:13.944+0000] {taskinstance.py:2865} INFO - Starting attempt 1 of 1
[2024-11-04T05:20:13.960+0000] {taskinstance.py:2888} INFO - Executing <Task(PythonOperator): send_slack_message> on 2024-11-04 05:19:40.405305+00:00
[2024-11-04T05:20:13.968+0000] {warnings.py:112} WARNING - /home/***/.local/lib/python3.12/site-packages/***/task/task_runner/standard_task_runner.py:70: DeprecationWarning: This process (pid=3572) is multi-threaded, use of fork() may lead to deadlocks in the child.
  pid = os.fork()

[2024-11-04T05:20:13.970+0000] {standard_task_runner.py:72} INFO - Started process 3573 to run task
[2024-11-04T05:20:13.971+0000] {standard_task_runner.py:104} INFO - Running: ['***', 'tasks', 'run', 'stock-market-summary', 'send_slack_message', 'manual__2024-11-04T05:19:40.405305+00:00', '--job-id', '276', '--raw', '--subdir', 'DAGS_FOLDER/stock_market_summary.py', '--cfg-path', '/tmp/tmplnvl7iwh']
[2024-11-04T05:20:13.974+0000] {standard_task_runner.py:105} INFO - Job 276: Subtask send_slack_message
[2024-11-04T05:20:14.020+0000] {task_command.py:467} INFO - Running <TaskInstance: stock-market-summary.send_slack_message manual__2024-11-04T05:19:40.405305+00:00 [running]> on host 5a41fc77ef88
[2024-11-04T05:20:14.096+0000] {taskinstance.py:3131} INFO - Exporting env vars: AIRFLOW_CTX_DAG_OWNER='***' AIRFLOW_CTX_DAG_ID='stock-market-summary' AIRFLOW_CTX_TASK_ID='send_slack_message' AIRFLOW_CTX_EXECUTION_DATE='2024-11-04T05:19:40.405305+00:00' AIRFLOW_CTX_TRY_NUMBER='1' AIRFLOW_CTX_DAG_RUN_ID='manual__2024-11-04T05:19:40.405305+00:00'
[2024-11-04T05:20:14.097+0000] {taskinstance.py:731} INFO - ::endgroup::
[2024-11-04T05:20:14.133+0000] {baseoperator.py:405} WARNING - SlackAPIPostOperator.execute cannot be called outside TaskInstance!
[2024-11-04T05:20:14.144+0000] {base.py:84} INFO - Retrieving connection 'slack_api_default'
[2024-11-04T05:20:14.684+0000] {taskinstance.py:3310} ERROR - Task failed with exception
Traceback (most recent call last):
  File "/home/airflow/.local/lib/python3.12/site-packages/airflow/models/taskinstance.py", line 767, in _execute_task
    result = _execute_callable(context=context, **execute_callable_kwargs)
             ^^^^^^^^^^^^^^^^^^^^^^^^^^^^^^^^^^^^^^^^^^^^^^^^^^^^^^^^^^^^^
  File "/home/airflow/.local/lib/python3.12/site-packages/airflow/models/taskinstance.py", line 733, in _execute_callable
    return ExecutionCallableRunner(
           ^^^^^^^^^^^^^^^^^^^^^^^^
  File "/home/airflow/.local/lib/python3.12/site-packages/airflow/utils/operator_helpers.py", line 252, in run
    return self.func(*args, **kwargs)
           ^^^^^^^^^^^^^^^^^^^^^^^^^^
  File "/home/airflow/.local/lib/python3.12/site-packages/airflow/models/baseoperator.py", line 406, in wrapper
    return func(self, *args, **kwargs)
           ^^^^^^^^^^^^^^^^^^^^^^^^^^^
  File "/home/airflow/.local/lib/python3.12/site-packages/airflow/operators/python.py", line 238, in execute
    return_value = self.execute_callable()
                   ^^^^^^^^^^^^^^^^^^^^^^^
  File "/home/airflow/.local/lib/python3.12/site-packages/airflow/operators/python.py", line 256, in execute_callable
    return runner.run(*self.op_args, **self.op_kwargs)
           ^^^^^^^^^^^^^^^^^^^^^^^^^^^^^^^^^^^^^^^^^^^
  File "/home/airflow/.local/lib/python3.12/site-packages/airflow/utils/operator_helpers.py", line 252, in run
    return self.func(*args, **kwargs)
           ^^^^^^^^^^^^^^^^^^^^^^^^^^
  File "/opt/airflow/dags/stock_market_summary.py", line 324, in send_slack_message
    stock_slack.execute(context=kwargs)
  File "/home/airflow/.local/lib/python3.12/site-packages/airflow/models/baseoperator.py", line 406, in wrapper
    return func(self, *args, **kwargs)
           ^^^^^^^^^^^^^^^^^^^^^^^^^^^
  File "/home/airflow/.local/lib/python3.12/site-packages/airflow/providers/slack/operators/slack.py", line 113, in execute
    self.hook.call(self.method, json=self.api_params)
  File "/home/airflow/.local/lib/python3.12/site-packages/airflow/providers/slack/hooks/slack.py", line 186, in call
    return self.client.api_call(api_method, **kwargs)
           ^^^^^^^^^^^^^^^^^^^^^^^^^^^^^^^^^^^^^^^^^^
  File "/home/airflow/.local/lib/python3.12/site-packages/slack_sdk/web/base_client.py", line 157, in api_call
    return self._sync_send(api_url=api_url, req_args=req_args)
           ^^^^^^^^^^^^^^^^^^^^^^^^^^^^^^^^^^^^^^^^^^^^^^^^^^^
  File "/home/airflow/.local/lib/python3.12/site-packages/slack_sdk/web/base_client.py", line 188, in _sync_send
    return self._urllib_api_call(
           ^^^^^^^^^^^^^^^^^^^^^^
  File "/home/airflow/.local/lib/python3.12/site-packages/slack_sdk/web/base_client.py", line 319, in _urllib_api_call
    ).validate()
      ^^^^^^^^^^
  File "/home/airflow/.local/lib/python3.12/site-packages/slack_sdk/web/slack_response.py", line 199, in validate
    raise e.SlackApiError(message=msg, response=self)
slack_sdk.errors.SlackApiError: The request to the Slack API failed. (url: https://slack.com/api/chat.postMessage)
The server responded with: {'ok': False, 'error': 'invalid_blocks', 'errors': ['no more than 50 items allowed [json-pointer:/blocks]'], 'response_metadata': {'messages': ['[ERROR] no more than 50 items allowed [json-pointer:/blocks]']}}
[2024-11-04T05:20:14.699+0000] {taskinstance.py:1225} INFO - Marking task as FAILED. dag_id=stock-market-summary, task_id=send_slack_message, run_id=manual__2024-11-04T05:19:40.405305+00:00, execution_date=20241104T051940, start_date=20241104T052013, end_date=20241104T052014
[2024-11-04T05:20:14.713+0000] {taskinstance.py:340} INFO - ::group::Post task execution logs
[2024-11-04T05:20:14.714+0000] {standard_task_runner.py:124} ERROR - Failed to execute job 276 for task send_slack_message (The request to the Slack API failed. (url: https://slack.com/api/chat.postMessage)
The server responded with: {'ok': False, 'error': 'invalid_blocks', 'errors': ['no more than 50 items allowed [json-pointer:/blocks]'], 'response_metadata': {'messages': ['[ERROR] no more than 50 items allowed [json-pointer:/blocks]']}}; 3573)
Traceback (most recent call last):
  File "/home/airflow/.local/lib/python3.12/site-packages/airflow/task/task_runner/standard_task_runner.py", line 117, in _start_by_fork
    ret = args.func(args, dag=self.dag)
          ^^^^^^^^^^^^^^^^^^^^^^^^^^^^^
  File "/home/airflow/.local/lib/python3.12/site-packages/airflow/cli/cli_config.py", line 49, in command
    return func(*args, **kwargs)
           ^^^^^^^^^^^^^^^^^^^^^
  File "/home/airflow/.local/lib/python3.12/site-packages/airflow/utils/cli.py", line 115, in wrapper
    return f(*args, **kwargs)
           ^^^^^^^^^^^^^^^^^^
  File "/home/airflow/.local/lib/python3.12/site-packages/airflow/cli/commands/task_command.py", line 483, in task_run
    task_return_code = _run_task_by_selected_method(args, _dag, ti)
                       ^^^^^^^^^^^^^^^^^^^^^^^^^^^^^^^^^^^^^^^^^^^^
  File "/home/airflow/.local/lib/python3.12/site-packages/airflow/cli/commands/task_command.py", line 256, in _run_task_by_selected_method
    return _run_raw_task(args, ti)
           ^^^^^^^^^^^^^^^^^^^^^^^
  File "/home/airflow/.local/lib/python3.12/site-packages/airflow/cli/commands/task_command.py", line 341, in _run_raw_task
    return ti._run_raw_task(
           ^^^^^^^^^^^^^^^^^
  File "/home/airflow/.local/lib/python3.12/site-packages/airflow/utils/session.py", line 97, in wrapper
    return func(*args, session=session, **kwargs)
           ^^^^^^^^^^^^^^^^^^^^^^^^^^^^^^^^^^^^^^
  File "/home/airflow/.local/lib/python3.12/site-packages/airflow/models/taskinstance.py", line 3004, in _run_raw_task
    return _run_raw_task(
           ^^^^^^^^^^^^^^
  File "/home/airflow/.local/lib/python3.12/site-packages/airflow/models/taskinstance.py", line 273, in _run_raw_task
    TaskInstance._execute_task_with_callbacks(
  File "/home/airflow/.local/lib/python3.12/site-packages/airflow/models/taskinstance.py", line 3158, in _execute_task_with_callbacks
    result = self._execute_task(context, task_orig)
             ^^^^^^^^^^^^^^^^^^^^^^^^^^^^^^^^^^^^^^
  File "/home/airflow/.local/lib/python3.12/site-packages/airflow/models/taskinstance.py", line 3182, in _execute_task
    return _execute_task(self, context, task_orig)
           ^^^^^^^^^^^^^^^^^^^^^^^^^^^^^^^^^^^^^^^
  File "/home/airflow/.local/lib/python3.12/site-packages/airflow/models/taskinstance.py", line 767, in _execute_task
    result = _execute_callable(context=context, **execute_callable_kwargs)
             ^^^^^^^^^^^^^^^^^^^^^^^^^^^^^^^^^^^^^^^^^^^^^^^^^^^^^^^^^^^^^
  File "/home/airflow/.local/lib/python3.12/site-packages/airflow/models/taskinstance.py", line 733, in _execute_callable
    return ExecutionCallableRunner(
           ^^^^^^^^^^^^^^^^^^^^^^^^
  File "/home/airflow/.local/lib/python3.12/site-packages/airflow/utils/operator_helpers.py", line 252, in run
    return self.func(*args, **kwargs)
           ^^^^^^^^^^^^^^^^^^^^^^^^^^
  File "/home/airflow/.local/lib/python3.12/site-packages/airflow/models/baseoperator.py", line 406, in wrapper
    return func(self, *args, **kwargs)
           ^^^^^^^^^^^^^^^^^^^^^^^^^^^
  File "/home/airflow/.local/lib/python3.12/site-packages/airflow/operators/python.py", line 238, in execute
    return_value = self.execute_callable()
                   ^^^^^^^^^^^^^^^^^^^^^^^
  File "/home/airflow/.local/lib/python3.12/site-packages/airflow/operators/python.py", line 256, in execute_callable
    return runner.run(*self.op_args, **self.op_kwargs)
           ^^^^^^^^^^^^^^^^^^^^^^^^^^^^^^^^^^^^^^^^^^^
  File "/home/airflow/.local/lib/python3.12/site-packages/airflow/utils/operator_helpers.py", line 252, in run
    return self.func(*args, **kwargs)
           ^^^^^^^^^^^^^^^^^^^^^^^^^^
  File "/opt/airflow/dags/stock_market_summary.py", line 324, in send_slack_message
    stock_slack.execute(context=kwargs)
  File "/home/airflow/.local/lib/python3.12/site-packages/airflow/models/baseoperator.py", line 406, in wrapper
    return func(self, *args, **kwargs)
           ^^^^^^^^^^^^^^^^^^^^^^^^^^^
  File "/home/airflow/.local/lib/python3.12/site-packages/airflow/providers/slack/operators/slack.py", line 113, in execute
    self.hook.call(self.method, json=self.api_params)
  File "/home/airflow/.local/lib/python3.12/site-packages/airflow/providers/slack/hooks/slack.py", line 186, in call
    return self.client.api_call(api_method, **kwargs)
           ^^^^^^^^^^^^^^^^^^^^^^^^^^^^^^^^^^^^^^^^^^
  File "/home/airflow/.local/lib/python3.12/site-packages/slack_sdk/web/base_client.py", line 157, in api_call
    return self._sync_send(api_url=api_url, req_args=req_args)
           ^^^^^^^^^^^^^^^^^^^^^^^^^^^^^^^^^^^^^^^^^^^^^^^^^^^
  File "/home/airflow/.local/lib/python3.12/site-packages/slack_sdk/web/base_client.py", line 188, in _sync_send
    return self._urllib_api_call(
           ^^^^^^^^^^^^^^^^^^^^^^
  File "/home/airflow/.local/lib/python3.12/site-packages/slack_sdk/web/base_client.py", line 319, in _urllib_api_call
    ).validate()
      ^^^^^^^^^^
  File "/home/airflow/.local/lib/python3.12/site-packages/slack_sdk/web/slack_response.py", line 199, in validate
    raise e.SlackApiError(message=msg, response=self)
slack_sdk.errors.SlackApiError: The request to the Slack API failed. (url: https://slack.com/api/chat.postMessage)
The server responded with: {'ok': False, 'error': 'invalid_blocks', 'errors': ['no more than 50 items allowed [json-pointer:/blocks]'], 'response_metadata': {'messages': ['[ERROR] no more than 50 items allowed [json-pointer:/blocks]']}}
[2024-11-04T05:20:14.748+0000] {local_task_job_runner.py:266} INFO - Task exited with return code 1
[2024-11-04T05:20:14.764+0000] {taskinstance.py:3900} INFO - 0 downstream tasks scheduled from follow-on schedule check
[2024-11-04T05:20:14.770+0000] {local_task_job_runner.py:245} INFO - ::endgroup::
